<robot name="tele">
	<link name="base_link">
	</link>

	<link name="wheel_left_link">
	</link>

	<link name="wheel_right_link">
	</link>

	<link name="camera_link">
	</link>


<!-- Standard convention:
	X	Forward
	Y	Left
	Z	Up
-->
	<joint name="base_to_camera" type="fixed">
		<parent link="base_link"/>
		<child link="camera_link"/>
		<origin xyz="0 0 0.2" rpy="0 0 0"/>
	</joint>

	<joint name="base_to_wheel_left" type="revolute">
		<parent link="base_link"/>
		<child link="wheel_left_link"/>
		<origin xyz="0 0.1 -0.1" rpy="0 0 0"/>
		<axis xyz="0 1 0"/>
	</joint>

	<joint name="base_to_wheel_right" type="revolute">
		<parent link="base_link"/>
		<child link="wheel_right_link"/>
		<origin xyz="0 -0.1 -0.1" rpy="0 0 0"/>
		<axis xyz="0 1 0"/>
	</joint>

</robot>
